2019-08-22 16:20:48,350 -  nornir.core -     INFO -        run() - Running task 'netmiko_send_command' with args {'command_string': 'show ip int brief'} on 2 hosts
2019-08-22 16:27:49,719 -  nornir.core -     INFO -        run() - Running task 'netmiko_send_command' with args {'command_string': 'show ip int brief'} on 2 hosts
2019-08-22 16:27:52,395 - nornir.core.task -    ERROR -      start() - Host 'cisco3': task 'netmiko_send_command' failed with traceback:
Traceback (most recent call last):
  File "/home/tmorales/VENV/py3_venv/local/lib/python3.6/site-packages/netmiko/base_connection.py", line 869, in establish_connection
    self.remote_conn_pre.connect(**ssh_connect_params)
  File "/home/tmorales/VENV/py3_venv/local/lib/python3.6/site-packages/paramiko/client.py", line 446, in connect
    passphrase,
  File "/home/tmorales/VENV/py3_venv/local/lib/python3.6/site-packages/paramiko/client.py", line 764, in _auth
    raise saved_exception
  File "/home/tmorales/VENV/py3_venv/local/lib/python3.6/site-packages/paramiko/client.py", line 751, in _auth
    self._transport.auth_password(username, password)
  File "/home/tmorales/VENV/py3_venv/local/lib/python3.6/site-packages/paramiko/transport.py", line 1509, in auth_password
    return self.auth_handler.wait_for_response(my_event)
  File "/home/tmorales/VENV/py3_venv/local/lib/python3.6/site-packages/paramiko/auth_handler.py", line 250, in wait_for_response
    raise e
paramiko.ssh_exception.AuthenticationException: Authentication failed.

During handling of the above exception, another exception occurred:

Traceback (most recent call last):
  File "/home/tmorales/VENV/py3_venv/local/lib/python3.6/site-packages/nornir/core/task.py", line 67, in start
    r = self.task(self, **self.params)
  File "/home/tmorales/VENV/py3_venv/local/lib/python3.6/site-packages/nornir/plugins/tasks/networking/netmiko_send_command.py", line 26, in netmiko_send_command
    net_connect = task.host.get_connection("netmiko", task.nornir.config)
  File "/home/tmorales/VENV/py3_venv/local/lib/python3.6/site-packages/nornir/core/inventory.py", line 302, in get_connection
    extras=conn.extras,
  File "/home/tmorales/VENV/py3_venv/local/lib/python3.6/site-packages/nornir/core/inventory.py", line 352, in open_connection
    configuration=configuration,
  File "/home/tmorales/VENV/py3_venv/local/lib/python3.6/site-packages/nornir/plugins/connections/netmiko.py", line 58, in open
    self.connection = ConnectHandler(**parameters)
  File "/home/tmorales/VENV/py3_venv/local/lib/python3.6/site-packages/netmiko/ssh_dispatcher.py", line 243, in ConnectHandler
    return ConnectionClass(*args, **kwargs)
  File "/home/tmorales/VENV/py3_venv/local/lib/python3.6/site-packages/netmiko/base_connection.py", line 317, in __init__
    self._open()
  File "/home/tmorales/VENV/py3_venv/local/lib/python3.6/site-packages/netmiko/base_connection.py", line 322, in _open
    self.establish_connection()
  File "/home/tmorales/VENV/py3_venv/local/lib/python3.6/site-packages/netmiko/base_connection.py", line 882, in establish_connection
    raise NetMikoAuthenticationException(msg)
netmiko.ssh_exception.NetMikoAuthenticationException: Authentication failure: unable to connect cisco_ios cisco3.lasthop.io:22
Authentication failed.

2019-08-25 16:26:27,197 -  nornir.core -     INFO -        run() - Running task 'netmiko_send_command' with args {'command_string': 'show ip int brief'} on 2 hosts
2019-08-25 16:26:29,984 - nornir.core.task -    ERROR -      start() - Host 'cisco3': task 'netmiko_send_command' failed with traceback:
Traceback (most recent call last):
  File "/home/tmorales/VENV/py3_venv/local/lib/python3.6/site-packages/netmiko/base_connection.py", line 869, in establish_connection
    self.remote_conn_pre.connect(**ssh_connect_params)
  File "/home/tmorales/VENV/py3_venv/local/lib/python3.6/site-packages/paramiko/client.py", line 446, in connect
    passphrase,
  File "/home/tmorales/VENV/py3_venv/local/lib/python3.6/site-packages/paramiko/client.py", line 764, in _auth
    raise saved_exception
  File "/home/tmorales/VENV/py3_venv/local/lib/python3.6/site-packages/paramiko/client.py", line 751, in _auth
    self._transport.auth_password(username, password)
  File "/home/tmorales/VENV/py3_venv/local/lib/python3.6/site-packages/paramiko/transport.py", line 1509, in auth_password
    return self.auth_handler.wait_for_response(my_event)
  File "/home/tmorales/VENV/py3_venv/local/lib/python3.6/site-packages/paramiko/auth_handler.py", line 250, in wait_for_response
    raise e
paramiko.ssh_exception.AuthenticationException: Authentication failed.

During handling of the above exception, another exception occurred:

Traceback (most recent call last):
  File "/home/tmorales/VENV/py3_venv/local/lib/python3.6/site-packages/nornir/core/task.py", line 67, in start
    r = self.task(self, **self.params)
  File "/home/tmorales/VENV/py3_venv/local/lib/python3.6/site-packages/nornir/plugins/tasks/networking/netmiko_send_command.py", line 26, in netmiko_send_command
    net_connect = task.host.get_connection("netmiko", task.nornir.config)
  File "/home/tmorales/VENV/py3_venv/local/lib/python3.6/site-packages/nornir/core/inventory.py", line 302, in get_connection
    extras=conn.extras,
  File "/home/tmorales/VENV/py3_venv/local/lib/python3.6/site-packages/nornir/core/inventory.py", line 352, in open_connection
    configuration=configuration,
  File "/home/tmorales/VENV/py3_venv/local/lib/python3.6/site-packages/nornir/plugins/connections/netmiko.py", line 58, in open
    self.connection = ConnectHandler(**parameters)
  File "/home/tmorales/VENV/py3_venv/local/lib/python3.6/site-packages/netmiko/ssh_dispatcher.py", line 243, in ConnectHandler
    return ConnectionClass(*args, **kwargs)
  File "/home/tmorales/VENV/py3_venv/local/lib/python3.6/site-packages/netmiko/base_connection.py", line 317, in __init__
    self._open()
  File "/home/tmorales/VENV/py3_venv/local/lib/python3.6/site-packages/netmiko/base_connection.py", line 322, in _open
    self.establish_connection()
  File "/home/tmorales/VENV/py3_venv/local/lib/python3.6/site-packages/netmiko/base_connection.py", line 882, in establish_connection
    raise NetMikoAuthenticationException(msg)
netmiko.ssh_exception.NetMikoAuthenticationException: Authentication failure: unable to connect cisco_ios cisco3.lasthop.io:22
Authentication failed.

2019-08-25 16:26:32,685 -  nornir.core -     INFO -        run() - Running task 'netmiko_send_command' with args {'command_string': 'show ip int brief'} on 2 hosts
2019-08-25 16:27:59,638 -  nornir.core -     INFO -        run() - Running task 'netmiko_send_command' with args {'command_string': 'show ip int brief'} on 2 hosts
2019-08-25 16:28:02,342 - nornir.core.task -    ERROR -      start() - Host 'cisco3': task 'netmiko_send_command' failed with traceback:
Traceback (most recent call last):
  File "/home/tmorales/VENV/py3_venv/local/lib/python3.6/site-packages/netmiko/base_connection.py", line 869, in establish_connection
    self.remote_conn_pre.connect(**ssh_connect_params)
  File "/home/tmorales/VENV/py3_venv/local/lib/python3.6/site-packages/paramiko/client.py", line 446, in connect
    passphrase,
  File "/home/tmorales/VENV/py3_venv/local/lib/python3.6/site-packages/paramiko/client.py", line 764, in _auth
    raise saved_exception
  File "/home/tmorales/VENV/py3_venv/local/lib/python3.6/site-packages/paramiko/client.py", line 751, in _auth
    self._transport.auth_password(username, password)
  File "/home/tmorales/VENV/py3_venv/local/lib/python3.6/site-packages/paramiko/transport.py", line 1509, in auth_password
    return self.auth_handler.wait_for_response(my_event)
  File "/home/tmorales/VENV/py3_venv/local/lib/python3.6/site-packages/paramiko/auth_handler.py", line 250, in wait_for_response
    raise e
paramiko.ssh_exception.AuthenticationException: Authentication failed.

During handling of the above exception, another exception occurred:

Traceback (most recent call last):
  File "/home/tmorales/VENV/py3_venv/local/lib/python3.6/site-packages/nornir/core/task.py", line 67, in start
    r = self.task(self, **self.params)
  File "/home/tmorales/VENV/py3_venv/local/lib/python3.6/site-packages/nornir/plugins/tasks/networking/netmiko_send_command.py", line 26, in netmiko_send_command
    net_connect = task.host.get_connection("netmiko", task.nornir.config)
  File "/home/tmorales/VENV/py3_venv/local/lib/python3.6/site-packages/nornir/core/inventory.py", line 302, in get_connection
    extras=conn.extras,
  File "/home/tmorales/VENV/py3_venv/local/lib/python3.6/site-packages/nornir/core/inventory.py", line 352, in open_connection
    configuration=configuration,
  File "/home/tmorales/VENV/py3_venv/local/lib/python3.6/site-packages/nornir/plugins/connections/netmiko.py", line 58, in open
    self.connection = ConnectHandler(**parameters)
  File "/home/tmorales/VENV/py3_venv/local/lib/python3.6/site-packages/netmiko/ssh_dispatcher.py", line 243, in ConnectHandler
    return ConnectionClass(*args, **kwargs)
  File "/home/tmorales/VENV/py3_venv/local/lib/python3.6/site-packages/netmiko/base_connection.py", line 317, in __init__
    self._open()
  File "/home/tmorales/VENV/py3_venv/local/lib/python3.6/site-packages/netmiko/base_connection.py", line 322, in _open
    self.establish_connection()
  File "/home/tmorales/VENV/py3_venv/local/lib/python3.6/site-packages/netmiko/base_connection.py", line 882, in establish_connection
    raise NetMikoAuthenticationException(msg)
netmiko.ssh_exception.NetMikoAuthenticationException: Authentication failure: unable to connect cisco_ios cisco3.lasthop.io:22
Authentication failed.

2019-08-25 16:28:05,005 -  nornir.core -     INFO -        run() - Running task 'netmiko_send_command' with args {'command_string': 'show ip int brief'} on 2 hosts
2019-08-25 16:33:04,596 -  nornir.core -     INFO -        run() - Running task 'netmiko_send_command' with args {'command_string': 'show ip int brief'} on 2 hosts
2019-08-25 16:33:07,199 - nornir.core.task -    ERROR -      start() - Host 'cisco3': task 'netmiko_send_command' failed with traceback:
Traceback (most recent call last):
  File "/home/tmorales/VENV/py3_venv/local/lib/python3.6/site-packages/netmiko/base_connection.py", line 869, in establish_connection
    self.remote_conn_pre.connect(**ssh_connect_params)
  File "/home/tmorales/VENV/py3_venv/local/lib/python3.6/site-packages/paramiko/client.py", line 446, in connect
    passphrase,
  File "/home/tmorales/VENV/py3_venv/local/lib/python3.6/site-packages/paramiko/client.py", line 764, in _auth
    raise saved_exception
  File "/home/tmorales/VENV/py3_venv/local/lib/python3.6/site-packages/paramiko/client.py", line 751, in _auth
    self._transport.auth_password(username, password)
  File "/home/tmorales/VENV/py3_venv/local/lib/python3.6/site-packages/paramiko/transport.py", line 1509, in auth_password
    return self.auth_handler.wait_for_response(my_event)
  File "/home/tmorales/VENV/py3_venv/local/lib/python3.6/site-packages/paramiko/auth_handler.py", line 250, in wait_for_response
    raise e
paramiko.ssh_exception.AuthenticationException: Authentication failed.

During handling of the above exception, another exception occurred:

Traceback (most recent call last):
  File "/home/tmorales/VENV/py3_venv/local/lib/python3.6/site-packages/nornir/core/task.py", line 67, in start
    r = self.task(self, **self.params)
  File "/home/tmorales/VENV/py3_venv/local/lib/python3.6/site-packages/nornir/plugins/tasks/networking/netmiko_send_command.py", line 26, in netmiko_send_command
    net_connect = task.host.get_connection("netmiko", task.nornir.config)
  File "/home/tmorales/VENV/py3_venv/local/lib/python3.6/site-packages/nornir/core/inventory.py", line 302, in get_connection
    extras=conn.extras,
  File "/home/tmorales/VENV/py3_venv/local/lib/python3.6/site-packages/nornir/core/inventory.py", line 352, in open_connection
    configuration=configuration,
  File "/home/tmorales/VENV/py3_venv/local/lib/python3.6/site-packages/nornir/plugins/connections/netmiko.py", line 58, in open
    self.connection = ConnectHandler(**parameters)
  File "/home/tmorales/VENV/py3_venv/local/lib/python3.6/site-packages/netmiko/ssh_dispatcher.py", line 243, in ConnectHandler
    return ConnectionClass(*args, **kwargs)
  File "/home/tmorales/VENV/py3_venv/local/lib/python3.6/site-packages/netmiko/base_connection.py", line 317, in __init__
    self._open()
  File "/home/tmorales/VENV/py3_venv/local/lib/python3.6/site-packages/netmiko/base_connection.py", line 322, in _open
    self.establish_connection()
  File "/home/tmorales/VENV/py3_venv/local/lib/python3.6/site-packages/netmiko/base_connection.py", line 882, in establish_connection
    raise NetMikoAuthenticationException(msg)
netmiko.ssh_exception.NetMikoAuthenticationException: Authentication failure: unable to connect cisco_ios cisco3.lasthop.io:22
Authentication failed.

2019-08-25 16:33:09,722 -  nornir.core -     INFO -        run() - Running task 'netmiko_send_command' with args {'command_string': 'show ip int brief'} on 2 hosts
2019-08-25 16:37:13,170 -  nornir.core -     INFO -        run() - Running task 'netmiko_send_command' with args {'command_string': 'show ip int brief'} on 2 hosts
2019-08-25 16:37:15,845 - nornir.core.task -    ERROR -      start() - Host 'cisco3': task 'netmiko_send_command' failed with traceback:
Traceback (most recent call last):
  File "/home/tmorales/VENV/py3_venv/local/lib/python3.6/site-packages/netmiko/base_connection.py", line 869, in establish_connection
    self.remote_conn_pre.connect(**ssh_connect_params)
  File "/home/tmorales/VENV/py3_venv/local/lib/python3.6/site-packages/paramiko/client.py", line 446, in connect
    passphrase,
  File "/home/tmorales/VENV/py3_venv/local/lib/python3.6/site-packages/paramiko/client.py", line 764, in _auth
    raise saved_exception
  File "/home/tmorales/VENV/py3_venv/local/lib/python3.6/site-packages/paramiko/client.py", line 751, in _auth
    self._transport.auth_password(username, password)
  File "/home/tmorales/VENV/py3_venv/local/lib/python3.6/site-packages/paramiko/transport.py", line 1509, in auth_password
    return self.auth_handler.wait_for_response(my_event)
  File "/home/tmorales/VENV/py3_venv/local/lib/python3.6/site-packages/paramiko/auth_handler.py", line 250, in wait_for_response
    raise e
paramiko.ssh_exception.AuthenticationException: Authentication failed.

During handling of the above exception, another exception occurred:

Traceback (most recent call last):
  File "/home/tmorales/VENV/py3_venv/local/lib/python3.6/site-packages/nornir/core/task.py", line 67, in start
    r = self.task(self, **self.params)
  File "/home/tmorales/VENV/py3_venv/local/lib/python3.6/site-packages/nornir/plugins/tasks/networking/netmiko_send_command.py", line 26, in netmiko_send_command
    net_connect = task.host.get_connection("netmiko", task.nornir.config)
  File "/home/tmorales/VENV/py3_venv/local/lib/python3.6/site-packages/nornir/core/inventory.py", line 302, in get_connection
    extras=conn.extras,
  File "/home/tmorales/VENV/py3_venv/local/lib/python3.6/site-packages/nornir/core/inventory.py", line 352, in open_connection
    configuration=configuration,
  File "/home/tmorales/VENV/py3_venv/local/lib/python3.6/site-packages/nornir/plugins/connections/netmiko.py", line 58, in open
    self.connection = ConnectHandler(**parameters)
  File "/home/tmorales/VENV/py3_venv/local/lib/python3.6/site-packages/netmiko/ssh_dispatcher.py", line 243, in ConnectHandler
    return ConnectionClass(*args, **kwargs)
  File "/home/tmorales/VENV/py3_venv/local/lib/python3.6/site-packages/netmiko/base_connection.py", line 317, in __init__
    self._open()
  File "/home/tmorales/VENV/py3_venv/local/lib/python3.6/site-packages/netmiko/base_connection.py", line 322, in _open
    self.establish_connection()
  File "/home/tmorales/VENV/py3_venv/local/lib/python3.6/site-packages/netmiko/base_connection.py", line 882, in establish_connection
    raise NetMikoAuthenticationException(msg)
netmiko.ssh_exception.NetMikoAuthenticationException: Authentication failure: unable to connect cisco_ios cisco3.lasthop.io:22
Authentication failed.

2019-08-25 16:37:18,545 -  nornir.core -     INFO -        run() - Running task 'netmiko_send_command' with args {'command_string': 'show ip int brief'} on 2 hosts
2019-08-25 16:40:04,407 -  nornir.core -     INFO -        run() - Running task 'netmiko_send_command' with args {'command_string': 'show ip int brief'} on 2 hosts
2019-08-25 16:40:07,086 - nornir.core.task -    ERROR -      start() - Host 'cisco3': task 'netmiko_send_command' failed with traceback:
Traceback (most recent call last):
  File "/home/tmorales/VENV/py3_venv/local/lib/python3.6/site-packages/netmiko/base_connection.py", line 869, in establish_connection
    self.remote_conn_pre.connect(**ssh_connect_params)
  File "/home/tmorales/VENV/py3_venv/local/lib/python3.6/site-packages/paramiko/client.py", line 446, in connect
    passphrase,
  File "/home/tmorales/VENV/py3_venv/local/lib/python3.6/site-packages/paramiko/client.py", line 764, in _auth
    raise saved_exception
  File "/home/tmorales/VENV/py3_venv/local/lib/python3.6/site-packages/paramiko/client.py", line 751, in _auth
    self._transport.auth_password(username, password)
  File "/home/tmorales/VENV/py3_venv/local/lib/python3.6/site-packages/paramiko/transport.py", line 1509, in auth_password
    return self.auth_handler.wait_for_response(my_event)
  File "/home/tmorales/VENV/py3_venv/local/lib/python3.6/site-packages/paramiko/auth_handler.py", line 250, in wait_for_response
    raise e
paramiko.ssh_exception.AuthenticationException: Authentication failed.

During handling of the above exception, another exception occurred:

Traceback (most recent call last):
  File "/home/tmorales/VENV/py3_venv/local/lib/python3.6/site-packages/nornir/core/task.py", line 67, in start
    r = self.task(self, **self.params)
  File "/home/tmorales/VENV/py3_venv/local/lib/python3.6/site-packages/nornir/plugins/tasks/networking/netmiko_send_command.py", line 26, in netmiko_send_command
    net_connect = task.host.get_connection("netmiko", task.nornir.config)
  File "/home/tmorales/VENV/py3_venv/local/lib/python3.6/site-packages/nornir/core/inventory.py", line 302, in get_connection
    extras=conn.extras,
  File "/home/tmorales/VENV/py3_venv/local/lib/python3.6/site-packages/nornir/core/inventory.py", line 352, in open_connection
    configuration=configuration,
  File "/home/tmorales/VENV/py3_venv/local/lib/python3.6/site-packages/nornir/plugins/connections/netmiko.py", line 58, in open
    self.connection = ConnectHandler(**parameters)
  File "/home/tmorales/VENV/py3_venv/local/lib/python3.6/site-packages/netmiko/ssh_dispatcher.py", line 243, in ConnectHandler
    return ConnectionClass(*args, **kwargs)
  File "/home/tmorales/VENV/py3_venv/local/lib/python3.6/site-packages/netmiko/base_connection.py", line 317, in __init__
    self._open()
  File "/home/tmorales/VENV/py3_venv/local/lib/python3.6/site-packages/netmiko/base_connection.py", line 322, in _open
    self.establish_connection()
  File "/home/tmorales/VENV/py3_venv/local/lib/python3.6/site-packages/netmiko/base_connection.py", line 882, in establish_connection
    raise NetMikoAuthenticationException(msg)
netmiko.ssh_exception.NetMikoAuthenticationException: Authentication failure: unable to connect cisco_ios cisco3.lasthop.io:22
Authentication failed.

2019-08-25 16:40:09,785 -  nornir.core -     INFO -        run() - Running task 'netmiko_send_command' with args {'command_string': 'show ip int brief'} on 2 hosts
2019-08-25 16:41:32,852 -  nornir.core -     INFO -        run() - Running task 'netmiko_send_command' with args {'command_string': 'show ip int brief'} on 2 hosts
2019-08-25 16:41:35,509 - nornir.core.task -    ERROR -      start() - Host 'cisco3': task 'netmiko_send_command' failed with traceback:
Traceback (most recent call last):
  File "/home/tmorales/VENV/py3_venv/local/lib/python3.6/site-packages/netmiko/base_connection.py", line 869, in establish_connection
    self.remote_conn_pre.connect(**ssh_connect_params)
  File "/home/tmorales/VENV/py3_venv/local/lib/python3.6/site-packages/paramiko/client.py", line 446, in connect
    passphrase,
  File "/home/tmorales/VENV/py3_venv/local/lib/python3.6/site-packages/paramiko/client.py", line 764, in _auth
    raise saved_exception
  File "/home/tmorales/VENV/py3_venv/local/lib/python3.6/site-packages/paramiko/client.py", line 751, in _auth
    self._transport.auth_password(username, password)
  File "/home/tmorales/VENV/py3_venv/local/lib/python3.6/site-packages/paramiko/transport.py", line 1509, in auth_password
    return self.auth_handler.wait_for_response(my_event)
  File "/home/tmorales/VENV/py3_venv/local/lib/python3.6/site-packages/paramiko/auth_handler.py", line 250, in wait_for_response
    raise e
paramiko.ssh_exception.AuthenticationException: Authentication failed.

During handling of the above exception, another exception occurred:

Traceback (most recent call last):
  File "/home/tmorales/VENV/py3_venv/local/lib/python3.6/site-packages/nornir/core/task.py", line 67, in start
    r = self.task(self, **self.params)
  File "/home/tmorales/VENV/py3_venv/local/lib/python3.6/site-packages/nornir/plugins/tasks/networking/netmiko_send_command.py", line 26, in netmiko_send_command
    net_connect = task.host.get_connection("netmiko", task.nornir.config)
  File "/home/tmorales/VENV/py3_venv/local/lib/python3.6/site-packages/nornir/core/inventory.py", line 302, in get_connection
    extras=conn.extras,
  File "/home/tmorales/VENV/py3_venv/local/lib/python3.6/site-packages/nornir/core/inventory.py", line 352, in open_connection
    configuration=configuration,
  File "/home/tmorales/VENV/py3_venv/local/lib/python3.6/site-packages/nornir/plugins/connections/netmiko.py", line 58, in open
    self.connection = ConnectHandler(**parameters)
  File "/home/tmorales/VENV/py3_venv/local/lib/python3.6/site-packages/netmiko/ssh_dispatcher.py", line 243, in ConnectHandler
    return ConnectionClass(*args, **kwargs)
  File "/home/tmorales/VENV/py3_venv/local/lib/python3.6/site-packages/netmiko/base_connection.py", line 317, in __init__
    self._open()
  File "/home/tmorales/VENV/py3_venv/local/lib/python3.6/site-packages/netmiko/base_connection.py", line 322, in _open
    self.establish_connection()
  File "/home/tmorales/VENV/py3_venv/local/lib/python3.6/site-packages/netmiko/base_connection.py", line 882, in establish_connection
    raise NetMikoAuthenticationException(msg)
netmiko.ssh_exception.NetMikoAuthenticationException: Authentication failure: unable to connect cisco_ios cisco3.lasthop.io:22
Authentication failed.

2019-08-25 16:41:38,177 -  nornir.core -     INFO -        run() - Running task 'netmiko_send_command' with args {'command_string': 'show ip int brief'} on 2 hosts
2019-08-25 16:43:26,709 -  nornir.core -     INFO -        run() - Running task 'netmiko_send_command' with args {'command_string': 'show ip int brief'} on 2 hosts
2019-08-25 16:43:29,365 - nornir.core.task -    ERROR -      start() - Host 'cisco3': task 'netmiko_send_command' failed with traceback:
Traceback (most recent call last):
  File "/home/tmorales/VENV/py3_venv/local/lib/python3.6/site-packages/netmiko/base_connection.py", line 869, in establish_connection
    self.remote_conn_pre.connect(**ssh_connect_params)
  File "/home/tmorales/VENV/py3_venv/local/lib/python3.6/site-packages/paramiko/client.py", line 446, in connect
    passphrase,
  File "/home/tmorales/VENV/py3_venv/local/lib/python3.6/site-packages/paramiko/client.py", line 764, in _auth
    raise saved_exception
  File "/home/tmorales/VENV/py3_venv/local/lib/python3.6/site-packages/paramiko/client.py", line 751, in _auth
    self._transport.auth_password(username, password)
  File "/home/tmorales/VENV/py3_venv/local/lib/python3.6/site-packages/paramiko/transport.py", line 1509, in auth_password
    return self.auth_handler.wait_for_response(my_event)
  File "/home/tmorales/VENV/py3_venv/local/lib/python3.6/site-packages/paramiko/auth_handler.py", line 250, in wait_for_response
    raise e
paramiko.ssh_exception.AuthenticationException: Authentication failed.

During handling of the above exception, another exception occurred:

Traceback (most recent call last):
  File "/home/tmorales/VENV/py3_venv/local/lib/python3.6/site-packages/nornir/core/task.py", line 67, in start
    r = self.task(self, **self.params)
  File "/home/tmorales/VENV/py3_venv/local/lib/python3.6/site-packages/nornir/plugins/tasks/networking/netmiko_send_command.py", line 26, in netmiko_send_command
    net_connect = task.host.get_connection("netmiko", task.nornir.config)
  File "/home/tmorales/VENV/py3_venv/local/lib/python3.6/site-packages/nornir/core/inventory.py", line 302, in get_connection
    extras=conn.extras,
  File "/home/tmorales/VENV/py3_venv/local/lib/python3.6/site-packages/nornir/core/inventory.py", line 352, in open_connection
    configuration=configuration,
  File "/home/tmorales/VENV/py3_venv/local/lib/python3.6/site-packages/nornir/plugins/connections/netmiko.py", line 58, in open
    self.connection = ConnectHandler(**parameters)
  File "/home/tmorales/VENV/py3_venv/local/lib/python3.6/site-packages/netmiko/ssh_dispatcher.py", line 243, in ConnectHandler
    return ConnectionClass(*args, **kwargs)
  File "/home/tmorales/VENV/py3_venv/local/lib/python3.6/site-packages/netmiko/base_connection.py", line 317, in __init__
    self._open()
  File "/home/tmorales/VENV/py3_venv/local/lib/python3.6/site-packages/netmiko/base_connection.py", line 322, in _open
    self.establish_connection()
  File "/home/tmorales/VENV/py3_venv/local/lib/python3.6/site-packages/netmiko/base_connection.py", line 882, in establish_connection
    raise NetMikoAuthenticationException(msg)
netmiko.ssh_exception.NetMikoAuthenticationException: Authentication failure: unable to connect cisco_ios cisco3.lasthop.io:22
Authentication failed.

2019-08-25 16:43:32,068 -  nornir.core -     INFO -        run() - Running task 'netmiko_send_command' with args {'command_string': 'show ip int brief'} on 2 hosts
