2019-10-27 15:08:13,757 -  nornir.core -     INFO -        run() - Running task 'netmiko_send_command' with args {'command_string': 'show run | i hostname', 'enable': True} on 1 hosts
2019-10-27 15:08:13,761 - nornir.core.task -    DEBUG -      start() - Host 'arista1': running task 'netmiko_send_command'
2019-10-27 15:23:35,074 -  nornir.core -     INFO -        run() - Running task 'netmiko_send_command' with args {'command_string': 'show run | i hostname', 'enable': True} on 1 hosts
2019-10-27 15:23:35,078 - nornir.core.task -    DEBUG -      start() - Host 'arista1': running task 'netmiko_send_command'
2019-10-27 15:24:33,421 -  nornir.core -     INFO -        run() - Running task 'netmiko_send_command' with args {'command_string': 'show run | i hostname'} on 1 hosts
2019-10-27 15:24:33,425 - nornir.core.task -    DEBUG -      start() - Host 'arista1': running task 'netmiko_send_command'
2019-10-27 15:24:34,190 - nornir.core.task -    ERROR -      start() - Host 'arista1': task 'netmiko_send_command' failed with traceback:
Traceback (most recent call last):
  File "/home/tmorales/VENV/py3_venv/local/lib/python3.6/site-packages/paramiko/transport.py", line 1528, in auth_password
    return self.auth_interactive(username, handler)
  File "/home/tmorales/VENV/py3_venv/local/lib/python3.6/site-packages/paramiko/transport.py", line 1633, in auth_interactive
    return self.auth_handler.wait_for_response(my_event)
  File "/home/tmorales/VENV/py3_venv/local/lib/python3.6/site-packages/paramiko/auth_handler.py", line 250, in wait_for_response
    raise e
paramiko.ssh_exception.AuthenticationException: Authentication failed.

During handling of the above exception, another exception occurred:

Traceback (most recent call last):
  File "/home/tmorales/VENV/py3_venv/local/lib/python3.6/site-packages/netmiko/base_connection.py", line 869, in establish_connection
    self.remote_conn_pre.connect(**ssh_connect_params)
  File "/home/tmorales/VENV/py3_venv/local/lib/python3.6/site-packages/paramiko/client.py", line 446, in connect
    passphrase,
  File "/home/tmorales/VENV/py3_venv/local/lib/python3.6/site-packages/paramiko/client.py", line 764, in _auth
    raise saved_exception
  File "/home/tmorales/VENV/py3_venv/local/lib/python3.6/site-packages/paramiko/client.py", line 751, in _auth
    self._transport.auth_password(username, password)
  File "/home/tmorales/VENV/py3_venv/local/lib/python3.6/site-packages/paramiko/transport.py", line 1531, in auth_password
    raise e
  File "/home/tmorales/VENV/py3_venv/local/lib/python3.6/site-packages/paramiko/transport.py", line 1509, in auth_password
    return self.auth_handler.wait_for_response(my_event)
  File "/home/tmorales/VENV/py3_venv/local/lib/python3.6/site-packages/paramiko/auth_handler.py", line 250, in wait_for_response
    raise e
paramiko.ssh_exception.BadAuthenticationType: Bad authentication type; allowed types: ['publickey', 'keyboard-interactive']

During handling of the above exception, another exception occurred:

Traceback (most recent call last):
  File "/home/tmorales/VENV/py3_venv/local/lib/python3.6/site-packages/nornir/core/task.py", line 67, in start
    r = self.task(self, **self.params)
  File "/home/tmorales/VENV/py3_venv/local/lib/python3.6/site-packages/nornir/plugins/tasks/networking/netmiko_send_command.py", line 26, in netmiko_send_command
    net_connect = task.host.get_connection("netmiko", task.nornir.config)
  File "/home/tmorales/VENV/py3_venv/local/lib/python3.6/site-packages/nornir/core/inventory.py", line 302, in get_connection
    extras=conn.extras,
  File "/home/tmorales/VENV/py3_venv/local/lib/python3.6/site-packages/nornir/core/inventory.py", line 352, in open_connection
    configuration=configuration,
  File "/home/tmorales/VENV/py3_venv/local/lib/python3.6/site-packages/nornir/plugins/connections/netmiko.py", line 58, in open
    self.connection = ConnectHandler(**parameters)
  File "/home/tmorales/VENV/py3_venv/local/lib/python3.6/site-packages/netmiko/ssh_dispatcher.py", line 243, in ConnectHandler
    return ConnectionClass(*args, **kwargs)
  File "/home/tmorales/VENV/py3_venv/local/lib/python3.6/site-packages/netmiko/base_connection.py", line 317, in __init__
    self._open()
  File "/home/tmorales/VENV/py3_venv/local/lib/python3.6/site-packages/netmiko/base_connection.py", line 322, in _open
    self.establish_connection()
  File "/home/tmorales/VENV/py3_venv/local/lib/python3.6/site-packages/netmiko/base_connection.py", line 882, in establish_connection
    raise NetMikoAuthenticationException(msg)
netmiko.ssh_exception.NetMikoAuthenticationException: Authentication failure: unable to connect arista_eos arista1.lasthop.io:22
Bad authentication type; allowed types: ['publickey', 'keyboard-interactive']

2019-10-27 15:24:41,310 -  nornir.core -     INFO -        run() - Running task 'netmiko_send_command' with args {'command_string': 'show run | i hostname'} on 1 hosts
2019-10-27 15:24:41,313 - nornir.core.task -    DEBUG -      start() - Host 'arista1': running task 'netmiko_send_command'
2019-10-27 15:28:14,324 -  nornir.core -     INFO -        run() - Running task 'netmiko_send_command' with args {'command_string': 'show run | i hostname'} on 1 hosts
2019-10-27 15:28:14,328 - nornir.core.task -    DEBUG -      start() - Host 'arista1': running task 'netmiko_send_command'
2019-10-27 15:30:45,261 -  nornir.core -     INFO -        run() - Running task 'netmiko_send_command' with args {'command_string': 'show run | i hostname'} on 1 hosts
2019-10-27 15:30:45,265 - nornir.core.task -    DEBUG -      start() - Host 'arista1': running task 'netmiko_send_command'
2019-10-27 15:31:09,438 -       nornir - CRITICAL -       main() - CRITICAL
2019-10-27 15:31:09,438 -       nornir -    ERROR -       main() - ERROR
2019-10-27 15:31:09,438 -       nornir -    DEBUG -       main() - DEBUG
